<mujoco model = "bhrGao">

	<compiler inertiafromgeom = "false" angle = "radian"/>

	<default>
		<joint limited = "true" stiffness = "1500" damping = "10" armature = "2.5"/>
		<geom condim = "4" material = "matgeom"/>
		<motor ctrlrange = "-314.0 314.0" ctrllimited = "true"/>
		<position kp = "15"/>
	</default>

	<option timestep = "0.004000" apirate = "144" iterations = "50"/>
	<option impratio = "0.1"/>
	<option tolerance = "1e-10" solver = "Newton"/>
	<option jacobian = "dense" cone = "pyramidal" gravity = "0.0 0.0 -9.8"/>

	<size nconmax = "50" njmax = "200" nstack = "10000"/>

	<visual>
		<map force = "0.5" zfar = "30"/>
		<rgba haze = "0.1 0.1 0.1 0"/>
		<quality shadowsize = "4096"/>
		<global offwidth = "1600" offheight = "1600"/>
	</visual>

	<asset>
		<texture type="skybox" builtin="gradient" rgb1="0.5 0.8 1.0" rgb2="0.4 0.6 0.7" width="512" height="512"/>
		<texture name="texplane" type="2d" builtin="checker" rgb1=".2 .3 .4" rgb2=".1 0.15 0.2" width="512" height="512" mark="cross" markrgb=".8 .8 .8"/>
		<texture name="texgeom" type="cube" builtin="flat" mark="cross" width="127" height="1278" rgb1="0.8 0.6 0.4" rgb2="0.8 0.6 0.4" markrgb="1 1 1" random="0.01"/>
		<material name="matplane" reflectance="0.3" texture="texplane" texrepeat="1 1" rgba ="0.9 0.9 0.9 1"/>
		<material name="matgeom" texture="texgeom" texuniform="true" rgba="0.8 0.6 .4 1"/>
		<material name="robots" shininess="0.5" reflectance="0.5"/>
	</asset>

	<worldbody>
		<geom name = "floor" pos = "0 0 0" size = "0 0 .25" type = "plane" material = "matplane" condim = "3" friction = "1.3 0.005 0.0001"/>
		<light directional = "true" diffuse = ".5 .5 .5" specular = "0.3 0.3 0.3" pos = "0 0 5" dir = "-0.25 0 -1" castshadow = "false"/>
		<light mode = "targetbodycom" target = "midbody" directional = "true" diffuse = ".7 .7 .7" specular = "0.3 0.3 0.3" pos = "0 0 4.0" dir = "0 0 -1" castshadow = "false"/>

		<body name = "midbody" pos = "0.000000 0.000000 0.720000">
			<freejoint name = "root"/>
			<inertial pos = "0 0 0" mass = "10.985000" diaginertia = "0.572910 0.333738 0.689018"/>
			<geom name = "midbody_geom" type = "capsule" fromto = "0 -0.080000 0 0 0.080000 0" size = "0.04" rgba = "0.14 0.16 0.16 1" material = "robots"/>
			<body name = "uppbody" pos = "-0.043377 0.000000 0.186707">
				<inertial pos = "0 0 0" mass = "23.140000" diaginertia = "0.360919 0.334445 0.227684"/>
				<joint name = "waist_yaw" type="hinge" pos = "0.052560 0.000000 -0.183798" axis = "0.000000 0.000000 1.000000" range = "-90 90"/>
				<geom name = "uppbody_geom" type = "capsule" fromto = "0 0 -0.183798 0 0 0.316202" size = "0.04" rgba = "0.14 0.16 0.16 1" material = "robots"/>
				<site name = "site_imu" pos = "0.042000 0.000000 -0.296000"/>
				<body name = "larm" pos = "0.014764 0.217177 -0.008181">
					<inertial pos = "0 0 0" mass = "7.988000" diaginertia = "0.183000 0.183200 0.116000"/>
					<joint name = "left_arm" type="hinge" pos = "-0.002204 -0.003377 0.083682" axis = "0.000000 1.000000 0.000000" range = "-90 90"/>
					<geom name = "larm_geom" type = "capsule" fromto = "0 0 0.083682 0 0 -0.216318" size = "0.04" rgba = "0.14 0.16 0.16 1" material = "robots"/>
				</body>
				<body name = "rarm" pos = "0.014764 -0.217177 -0.008181">
					<inertial pos = "0 0 0" mass = "7.988000" diaginertia = "0.183000 0.183200 0.116000"/>
					<joint name = "right_arm" type="hinge" pos = "-0.002204 0.003377 0.083682" axis = "0.000000 1.000000 0.000000" range = "-90 90"/>
					<geom name = "rarm_geom" type = "capsule" fromto = "0 0 0.083682 0 0 -0.216318" size = "0.04" rgba = "0.14 0.16 0.16 1" material = "robots"/>
				</body>
			</body>
			<body name = "lhip" pos = "-0.031747 0.086460 -0.184091">
				<inertial pos = "0 0 0" mass = "4.316000" diaginertia = "0.062711 0.053173 0.042038"/>
				<joint name = "left_leg_1" type="hinge" pos = "0.000930 0.003540 -0.015400" axis = "0.000000 0.000000 1.000000" range = "-90 90"/>
				<body name = "lthigh" pos = "-0.000207 -0.000176 -0.080186">
					<inertial pos = "0 0 0" mass = "5.573000" diaginertia = "0.096839 0.099135 0.018810"/>
					<joint name = "left_leg_3" type="hinge" pos = "0.001137 -0.003784 0.064786" axis = "0.000000 1.000000 0.000000" range = "-90 90"/>
					<joint name = "left_leg_2" type="hinge" pos = "0.001137 -0.003784 0.064786" axis = "1.000000 0.000000 0.000000" range = "-90 90"/>
					<geom name = "lthigh_geom" type = "capsule" fromto = "0 0 0.064786 0 0 -0.255214" size = "0.04" rgba = "0.14 0.16 0.16 1" material = "robots"/>
					<body name = "lshank" pos = "0.005837 -0.007924 -0.440114">
						<inertial pos = "0 0 0" mass = "1.982000" diaginertia = "0.090082 0.088496 0.006453"/>
						<joint name = "left_leg_4" type="hinge" pos = "0.045300 0.004140 0.174400" axis = "0.000000 1.000000 0.000000" range = "-90 90"/>
						<geom name = "lshank_geom" type = "capsule" fromto = "0 0 0.174400 0 0 -0.145600" size = "0.04" rgba = "0.14 0.16 0.16 1" material = "robots"/>
						<body name = "lankle" pos = "-0.008740 0.005490 -0.187260">
							<inertial pos = "0 0 0" mass = "1.405000" diaginertia = "0.002942 0.006115 0.005134"/>
							<joint name = "left_l3eg_5" type="hinge" pos = "0.004040 -0.001350 0.031660" axis = "0.000000 1.000000 0.000000" range = "-90 90"/>
							<joint name = "left_leg_6" type="hinge" pos = "0.004040 -0.001350 0.031660" axis = "1.000000 0.000000 0.000000" range = "-90 90"/>
							<body name = "lfoot" pos = "0.035000 0.020000 -0.015000">
								<inertial pos = "0 0 0" mass = "1.166800" diaginertia = "0.002068 0.005036 0.005344"/>
								<geom name = "lfoot" type = "box" size = "0.135000 0.075000 0.010000" rgba = "0.14 0.16 0.16 1" material = "robots"/>
								<site name = "site_lforcesensor" pos = "-0.035000 -0.020000 0.080000"/>
							</body>
						</body>
					</body>
				</body>
			</body>
			<body name = "rhip" pos = "-0.031747 -0.086460 -0.184091">
				<inertial pos = "0 0 0" mass = "4.316000" diaginertia = "0.062711 0.053173 0.042038"/>
				<joint name = "right_leg_1" type="hinge" pos = "0.000930 -0.003540 -0.015400" axis = "0.000000 0.000000 1.000000" range = "-90 90"/>
				<body name = "rthigh" pos = "-0.000207 0.000176 -0.080186">
					<inertial pos = "0 0 0" mass = "5.573000" diaginertia = "0.096839 0.099135 0.018810"/>
					<joint name = "right_leg_3" type="hinge" pos = "0.001137 0.003784 0.064786" axis = "0.000000 1.000000 0.000000" range = "-90 90"/>
					<joint name = "right_leg_2" type="hinge" pos = "0.001137 0.003784 0.064786" axis = "1.000000 0.000000 0.000000" range = "-90 90"/>
					<geom name = "rthigh_geom" type = "capsule" fromto = "0 0 0.064786 0 0 -0.255214" size = "0.04" rgba = "0.14 0.16 0.16 1" material = "robots"/>
					<body name = "rshank" pos = "0.005837 0.007924 -0.440114">
						<inertial pos = "0 0 0" mass = "1.982000" diaginertia = "0.090082 0.088496 0.006453"/>
						<joint name = "right_leg_4" type="hinge" pos = "0.045300 -0.004140 0.174400" axis = "0.000000 1.000000 0.000000" range = "-90 90"/>
						<geom name = "rshank_geom" type = "capsule" fromto = "0 0 0.174400 0 0 -0.145600" size = "0.04" rgba = "0.14 0.16 0.16 1" material = "robots"/>
						<body name = "rankle" pos = "-0.008740 -0.005490 -0.187260">
							<inertial pos = "0 0 0" mass = "1.405000" diaginertia = "0.002942 0.006115 0.005134"/>
							<joint name = "right_l3eg_5" type="hinge" pos = "0.004040 0.001350 0.031660" axis = "0.000000 1.000000 0.000000" range = "-90 90"/>
							<joint name = "right_leg_6" type="hinge" pos = "0.004040 0.001350 0.031660" axis = "1.000000 0.000000 0.000000" range = "-90 90"/>
							<body name = "rfoot" pos = "0.035000 0.020000 -0.015000">
								<inertial pos = "0 0 0" mass = "1.166800" diaginertia = "0.002068 0.005036 0.005344"/>
								<geom name = "rfoot" type = "box" size = "0.135000 0.075000 0.010000" rgba = "0.14 0.16 0.16 1" material = "robots"/>
								<site name = "site_rforcesensor" pos = "-0.035000 -0.020000 0.080000"/>
							</body>
						</body>
					</body>
				</body>
			</body>
		</body>
		<body name = "" pos = "0.000000 0.000000 0.000000">
			<inertial pos = "0 0 0" mass = "0.000000" diaginertia = "0.000000 0.000000 0.000000"/>
		</body>
	</worldbody>

	<sensor>
		<force name = "lforcesonsor" site = "site_lforcesensor" cutoff = "2000.0"/>
		<torque name = "ltorquesonsor" site = "site_lforcesensor" cutoff = "2000.0"/>
		<force name = "rforcesonsor" site = "site_rforcesensor" cutoff = "2000.0"/>
		<torque name = "rtorquesonsor" site = "site_rforcesensor" cutoff = "2000.0"/>
	</sensor>

	<actuator>
		<position name = "waist_yaw" gear = "100.00000" joint = "waist_yaw"/>
		<position name = "left_arm" gear = "100.00000" joint = "left_arm"/>
		<position name = "right_arm" gear = "100.00000" joint = "right_arm"/>
		<position name = "left_leg_1" gear = "100.00000" joint = "left_leg_1"/>
		<position name = "left_leg_3" gear = "100.00000" joint = "left_leg_3"/>
		<position name = "left_leg_2" gear = "100.00000" joint = "left_leg_2"/>
		<position name = "left_leg_4" gear = "100.00000" joint = "left_leg_4"/>
		<position name = "left_l3eg_5" gear = "100.00000" joint = "left_l3eg_5"/>
		<position name = "left_leg_6" gear = "100.00000" joint = "left_leg_6"/>
		<position name = "right_leg_1" gear = "100.00000" joint = "right_leg_1"/>
		<position name = "right_leg_3" gear = "100.00000" joint = "right_leg_3"/>
		<position name = "right_leg_2" gear = "100.00000" joint = "right_leg_2"/>
		<position name = "right_leg_4" gear = "100.00000" joint = "right_leg_4"/>
		<position name = "right_l3eg_5" gear = "100.00000" joint = "right_l3eg_5"/>
		<position name = "right_leg_6" gear = "100.00000" joint = "right_leg_6"/>
	</actuator>

	<contact>
		<exclude body1 = "midbody" body2 = "uppbody"/>
		<exclude body1 = "midbody" body2 = "larm"/>
		<exclude body1 = "midbody" body2 = "rarm"/>
		<exclude body1 = "midbody" body2 = "lhip"/>
		<exclude body1 = "midbody" body2 = "lthigh"/>
		<exclude body1 = "midbody" body2 = "lshank"/>
		<exclude body1 = "midbody" body2 = "lankle"/>
		<exclude body1 = "midbody" body2 = "rhip"/>
		<exclude body1 = "midbody" body2 = "rthigh"/>
		<exclude body1 = "midbody" body2 = "rshank"/>
		<exclude body1 = "midbody" body2 = "rankle"/>
		<exclude body1 = "uppbody" body2 = "larm"/>
		<exclude body1 = "uppbody" body2 = "rarm"/>
		<exclude body1 = "uppbody" body2 = "lthigh"/>
		<exclude body1 = "uppbody" body2 = "lshank"/>
		<exclude body1 = "uppbody" body2 = "lankle"/>
		<exclude body1 = "uppbody" body2 = "rthigh"/>
		<exclude body1 = "uppbody" body2 = "rshank"/>
		<exclude body1 = "uppbody" body2 = "rankle"/>
		<exclude body1 = "larm" body2 = "rarm"/>
		<exclude body1 = "larm" body2 = "lhip"/>
		<exclude body1 = "larm" body2 = "lthigh"/>
		<exclude body1 = "larm" body2 = "lshank"/>
		<exclude body1 = "larm" body2 = "lankle"/>
		<exclude body1 = "larm" body2 = "rhip"/>
		<exclude body1 = "larm" body2 = "rthigh"/>
		<exclude body1 = "larm" body2 = "rshank"/>
		<exclude body1 = "larm" body2 = "rankle"/>
		<exclude body1 = "rarm" body2 = "lhip"/>
		<exclude body1 = "rarm" body2 = "lthigh"/>
		<exclude body1 = "rarm" body2 = "lshank"/>
		<exclude body1 = "rarm" body2 = "lankle"/>
		<exclude body1 = "rarm" body2 = "rhip"/>
		<exclude body1 = "rarm" body2 = "rthigh"/>
		<exclude body1 = "rarm" body2 = "rshank"/>
		<exclude body1 = "rarm" body2 = "rankle"/>
		<exclude body1 = "lhip" body2 = "lthigh"/>
		<exclude body1 = "lhip" body2 = "lshank"/>
		<exclude body1 = "lhip" body2 = "lankle"/>
		<exclude body1 = "lhip" body2 = "rhip"/>
		<exclude body1 = "lhip" body2 = "rthigh"/>
		<exclude body1 = "lhip" body2 = "rshank"/>
		<exclude body1 = "lhip" body2 = "rankle"/>
		<exclude body1 = "lthigh" body2 = "lshank"/>
		<exclude body1 = "lthigh" body2 = "lankle"/>
		<exclude body1 = "lthigh" body2 = "rthigh"/>
		<exclude body1 = "lthigh" body2 = "rshank"/>
		<exclude body1 = "lthigh" body2 = "rankle"/>
		<exclude body1 = "lshank" body2 = "lankle"/>
		<exclude body1 = "lshank" body2 = "rthigh"/>
		<exclude body1 = "lshank" body2 = "rshank"/>
		<exclude body1 = "lshank" body2 = "rankle"/>
		<exclude body1 = "lankle" body2 = "rthigh"/>
		<exclude body1 = "lankle" body2 = "rshank"/>
		<exclude body1 = "lankle" body2 = "rankle"/>
		<exclude body1 = "rhip" body2 = "rthigh"/>
		<exclude body1 = "rhip" body2 = "rshank"/>
		<exclude body1 = "rhip" body2 = "rankle"/>
		<exclude body1 = "rthigh" body2 = "rshank"/>
		<exclude body1 = "rthigh" body2 = "rankle"/>
		<exclude body1 = "rshank" body2 = "rankle"/>
	</contact>

</mujoco>
